Traceback (most recent call last):
  File "/usr/local/python/3.10.13/lib/python3.10/site-packages/jupyter_cache/executors/utils.py", line 58, in single_nb_execution
    executenb(
  File "/home/codespace/.local/lib/python3.10/site-packages/nbclient/client.py", line 1314, in execute
    return NotebookClient(nb=nb, resources=resources, km=km, **kwargs).execute()
  File "/home/codespace/.local/lib/python3.10/site-packages/jupyter_core/utils/__init__.py", line 165, in wrapped
    return loop.run_until_complete(inner)
  File "/usr/local/python/3.10.13/lib/python3.10/asyncio/base_events.py", line 649, in run_until_complete
    return future.result()
  File "/home/codespace/.local/lib/python3.10/site-packages/nbclient/client.py", line 709, in async_execute
    await self.async_execute_cell(
  File "/home/codespace/.local/lib/python3.10/site-packages/nbclient/client.py", line 1062, in async_execute_cell
    await self._check_raise_for_error(cell, cell_index, exec_reply)
  File "/home/codespace/.local/lib/python3.10/site-packages/nbclient/client.py", line 918, in _check_raise_for_error
    raise CellExecutionError.from_cell_and_msg(cell, exec_reply_content)
nbclient.exceptions.CellExecutionError: An error occurred while executing the following cell:
------------------
C = RowSwap(,0,2)
print(1)
B2 = RowAdd(B1,0,1,-4)
print(B2)
B3 = RowAdd(B2,0,2,-2)
print(B3)
B4 = RowSwap(B3,1,2)
print(B4)
B5 = RowAdd(B4,1,2,-2)
print(B5)


------------------


[0;36m  Cell [0;32mIn[35], line 1[0;36m[0m
[0;31m    C = RowSwap(,0,2)[0m
[0m                ^[0m
[0;31mSyntaxError[0m[0;31m:[0m invalid syntax


